Workbook

Sheet IO_Table_2025(RAW)
A1: Kode | B1: Deskripsi | C1: 1 | D1: 2 | E1: 3 | F1: 4 | G1: 5 | H1: 6 | I1: 7 | J1: 8 | K1: 9 | L1: 10 | M1: 11 | N1: 12 | O1: 13 | P1: 14 | Q1: 15 | R1: 16 | S1: 17 | T1: 18 | U1: 19 | V1: 20 | W1: 21 | X1: 22 | Y1: 23 | Z1: 24 | AA1: 25 | AB1: 26 | AC1: 27 | AD1: 28 | AE1: 29 | AF1: 30 | AG1: 31 | AH1: 32 | AI1: 33 | AJ1: 34 | AK1: 35 | AL1: 36 | AM1: 37 | AN1: 38 | AO1: 39 | AP1: 40 | AQ1: 41 | AR1: 42 | AS1: 43 | AT1: 44 | AU1: 45 | AV1: 46 | AW1: 47 | AX1: 48 | AY1: 49 | AZ1: 50 | BA1: 51 | BB1: 52 | BC1: 53 | BD1: 54 | BE1: 55 | BF1: 180 | BG1: 301 | BH1: 302 | BI1: 303 | BJ1: 304 | BK1: 305 | BL1: 309 | BM1: 310 | BN1: 409 | BO1: 509 | BP1: 600 | BQ1: 700
A2: 1 | B2: Pertanian Tanaman Pangan | C2: 1069045 | D2: 0 | E2: 0 | F2: 0 | G2: 0 | H2: 697.3892 | I2: 0 | J2: 0 | K2: 21452.074 | L2: 0 | M2: 0 | N2: 0 | O2: 0 | P2: 0 | Q2: 16469292 | R2: 0 | S2: 0 | T2: 0 | U2: 0 | V2: 0 | W2: 5192.8969 | X2: 0 | Y2: 2043.1564 | Z2: 0 | AA2: 0 | AB2: 0 | AC2: 0 | AD2: 0 | AE2: 0 | AF2: 0 | AG2: 0 | AH2: 0 | AI2: 0 | AJ2: 0 | AK2: 0 | AL2: 0 | AM2: 0 | AN2: 0 | AO2: 0 | AP2: 0 | AQ2: 0 | AR2: 6373.7154 | AS2: 222413.56 | AT2: 0 | AU2: 0 | AV2: 0 | AW2: 0 | AX2: 0 | AY2: 0 | AZ2: 0 | BA2: 70927.807 | BB2: 5489.5984 | BC2: 7671.5013 | BD2: 34190.168 | BE2: 0 | BF2: 17914789 | BG2: 369043.3 | BH2: 0 | BI2: 0 | BJ2: 73419.347 | BK2: 271170 | BL2: 713632.64 | BM2: 18628421 | BN2: 0 | BO2: 0 | BP2: 18628421 | BQ2: 18628421
A3: 2 | B3: Pertanian Tanaman Hortikultura Semusim, Hortikultura Tahunan, dan Lainnya | C3: 0 | D3: 75321.678 | E3: 0 | F3: 0 | G3: 76.1594 | H3: 0 | I3: 0 | J3: 0 | K3: 0 | L3: 0 | M3: 0 | N3: 0 | O3: 0 | P3: 0 | Q3: 1238534 | R3: 0 | S3: 0 | T3: 0 | U3: 0 | V3: 0 | W3: 10570.457 | X3: 6.6199 | Y3: 0 | Z3: 0 | AA3: 0 | AB3: 0 | AC3: 0 | AD3: 19.6128 | AE3: 0 | AF3: 27.5495 | AG3: 0 | AH3: 0 | AI3: 31036.814 | AJ3: 0 | AK3: 0 | AL3: 3636.1612 | AM3: 0 | AN3: 927.9023 | AO3: 0 | AP3: 16386.871 | AQ3: 0 | AR3: 20599.848 | AS3: 541937.3 | AT3: 0.3453 | AU3: 242.0894 | AV3: 0 | AW3: 0 | AX3: 0 | AY3: 0 | AZ3: 0 | BA3: 2170.2044 | BB3: 2348.2498 | BC3: 57539.736 | BD3: 4049.9285 | BE3: 0 | BF3: 2005431.5 | BG3: 4139011 | BH3: 0 | BI3: 179801.13 | BJ3: 52261.44 | BK3: 601604.07 | BL3: 4972677.7 | BM3: 6978109.2 | BN3: 0 | BO3: 0 | BP3: 6978109.2 | BQ3: 6978109.2
A4: 3 | B4: Karet | C4: 0 | D4: 0 | E4: 1091870 | F4: 0 | G4: 0 | H4: 0 | I4: 0 | J4: 0 | K4: 0 | L4: 0 | M4: 0 | N4: 0 | O4: 0 | P4: 0 | Q4: 0 | R4: 0 | S4: 0 | T4: 0 | U4: 0 | V4: 0 | W4: 0 | X4: 11154452 | Y4: 0 | Z4: 0 | AA4: 0 | AB4: 0 | AC4: 0 | AD4: 0 | AE4: 0 | AF4: 0 | AG4: 0 | AH4: 0 | AI4: 0 | AJ4: 0 | AK4: 6820.7965 | AL4: 0 | AM4: 0 | AN4: 0 | AO4: 0 | AP4: 0 | AQ4: 0 | AR4: 0 | AS4: 0 | AT4: 0 | AU4: 0 | AV4: 0 | AW4: 0 | AX4: 0 | AY4: 0 | AZ4: 0 | BA4: 0 | BB4: 0 | BC4: 0 | BD4: 0 | BE4: 0 | BF4: 12253142 | BG4: 0 | BH4: 0 | BI4: 0 | BJ4: 0 | BK4: 64.5775 | BL4: 64.5775 | BM4: 12253207 | BN4: 0 | BO4: 0 | BP4: 12253207 | BQ4: 12253207
A5: 4 | B5: Kelapa Sawit | C5: 0 | D5: 0 | E5: 0 | F5: 2061576.3 | G5: 0 | H5: 0 | I5: 0 | J5: 0 | K5: 0 | L5: 0 | M5: 0 | N5: 0 | O5: 0 | P5: 0 | Q5: 20717828 | R5: 0 | S5: 0 | T5: 0 | U5: 0 | V5: 0 | W5: 0 | X5: 0 | Y5: 0 | Z5: 0 | AA5: 0 | AB5: 0 | AC5: 0 | AD5: 0 | AE5: 0 | AF5: 0 | AG5: 0 | AH5: 0 | AI5: 0 | AJ5: 0 | AK5: 15026.465 | AL5: 0 | AM5: 0 | AN5: 0 | AO5: 0 | AP5: 0 | AQ5: 0 | AR5: 0 | AS5: 0 | AT5: 0 | AU5: 0 | AV5: 0 | AW5: 0 | AX5: 0 | AY5: 0 | AZ5: 0 | BA5: 0 | BB5: 0 | BC5: 0 | BD5: 0 | BE5: 0 | BF5: 22794431 | BG5: 0 | BH5: 0 | BI5: 0 | BJ5: 0 | BK5: 876645.07 | BL5: 876645.07 | BM5: 23671076 | BN5: 0 | BO5: 0 | BP5: 23671076 | BQ5: 23671076
A6: 5 | B6: Tanaman Perkebunan lainnya | C6: 0 | D6: 0 | E6: 0 | F6: 0 | G6: 313476.6 | H6: 0 | I6: 0 | J6: 0 | K6: 0 | L6: 0 | M6: 0 | N6: 0 | O6: 0 | P6: 0 | Q6: 247988.19 | R6: 0 | S6: 0 | T6: 21.748 | U6: 37.7579 | V6: 0 | W6: 766241.01 | X6: 3206.6985 | Y6: 12.9868 | Z6: 0 | AA6: 0 | AB6: 3.6649 | AC6: 0 | AD6: 1969.0134 | AE6: 2189.6912 | AF6: 0 | AG6: 0 | AH6: 0 | AI6: 263.638 | AJ6: 0 | AK6: 0 | AL6: 0 | AM6: 0 | AN6: 0 | AO6: 0 | AP6: 0 | AQ6: 0 | AR6: 87.1216 | AS6: 164973.83 | AT6: 0 | AU6: 0 | AV6: 0 | AW6: 0 | AX6: 0 | AY6: 0 | AZ6: 0 | BA6: 21.8348 | BB6: 117.2845 | BC6: 7811.2873 | BD6: 964.4516 | BE6: 0 | BF6: 1509386.8 | BG6: 172325.96 | BH6: 0 | BI6: 1543475.4 | BJ6: 80904.957 | BK6: 1542357.3 | BL6: 3339063.7 | BM6: 4848450.5 | BN6: 0 | BO6: 0 | BP6: 4848450.5 | BQ6: 4848450.5
A7: 6 | B7: Peternakan | C7: 28631.704 | D7: 61683.885 | E7: 0 | F7: 1085.4154 | G7: 327.8782 | H7: 134988.8 | I7: 6920.5818 | J7: 813.2388 | K7: 168.4107 | L7: 0 | M7: 0 | N7: 0 | O7: 0 | P7: 0 | Q7: 5249641.1 | R7: 0 | S7: 4803.2183 | T7: 22.4412 | U7: 0 | V7: 0 | W7: 433.5162 | X7: 0 | Y7: 0 | Z7: 0 | AA7: 0 | AB7: 0 | AC7: 0 | AD7: 0.0098 | AE7: 0 | AF7: 0 | AG7: 0 | AH7: 0 | AI7: 0 | AJ7: 0 | AK7: 0 | AL7: 0 | AM7: 0 | AN7: 0 | AO7: 0 | AP7: 0 | AQ7: 0 | AR7: 38344.743 | AS7: 683315.58 | AT7: 0 | AU7: 0 | AV7: 0 | AW7: 0 | AX7: 0 | AY7: 0 | AZ7: 0 | BA7: 47729.646 | BB7: 13354.979 | BC7: 41265.269 | BD7: 32619.371 | BE7: 0 | BF7: 6346149.8 | BG7: 2947885.3 | BH7: 0 | BI7: 3614047.6 | BJ7: 198195.78 | BK7: 32740.831 | BL7: 6792869.5 | BM7: 13139019 | BN7: 0 | BO7: 0 | BP7: 13139019 | BQ7: 13139019
A8: 7 | B8: Jasa Pertanian dan Perburuan | C8: 197662.84 | D8: 51424.309 | E8: 0 | F8: 1041080.8 | G8: 779061.32 | H8: 0 | I8: 0 | J8: 0 | K8: 0 | L8: 0 | M8: 0 | N8: 0 | O8: 0 | P8: 0 | Q8: 0 | R8: 0 | S8: 0 | T8: 0 | U8: 0 | V8: 0 | W8: 0 | X8: 0 | Y8: 0 | Z8: 0 | AA8: 0 | AB8: 0 | AC8: 0 | AD8: 0 | AE8: 0 | AF8: 0 | AG8: 0 | AH8: 0 | AI8: 0 | AJ8: 0 | AK8: 0 | AL8: 0 | AM8: 0 | AN8: 0 | AO8: 0 | AP8: 0 | AQ8: 0 | AR8: 0 | AS8: 0 | AT8: 0 | AU8: 0 | AV8: 0 | AW8: 0 | AX8: 0 | AY8: 0 | AZ8: 0 | BA8: 7224.8618 | BB8: 0 | BC8: 0 | BD8: 0 | BE8: 0 | BF8: 2076454.1 | BG8: 4523.2212 | BH8: 0 | BI8: 0 | BJ8: 0 | BK8: 0 | BL8: 4523.2212 | BM8: 2080977.3 | BN8: 0 | BO8: 0 | BP8: 2080977.3 | BQ8: 2080977.3
A9: 8 | B9: Kehutanan dan Penebangan Kayu | C9: 1.0454 | D9: 620.0298 | E9: 0 | F9: 19104.265 | G9: 1560.9711 | H9: 6494.6021 | I9: 2.0291 | J9: 119124.84 | K9: 678.5901 | L9: 0 | M9: 33769.315 | N9: 0 | O9: 5412.3937 | P9: 1432.2475 | Q9: 80449.067 | R9: 0 | S9: 3094.5964 | T9: 2.9143 | U9: 571531.65 | V9: 669693.81 | W9: 35875.712 | X9: 12354.974 | Y9: 132.0165 | Z9: 0.3821 | AA9: 66.4564 | AB9: 0 | AC9: 254.7084 | AD9: 3400.5184 | AE9: 3163.057 | AF9: 0 | AG9: 0 | AH9: 0 | AI9: 3160108.9 | AJ9: 3260.6437 | AK9: 1492.2123 | AL9: 0 | AM9: 0 | AN9: 0 | AO9: 0 | AP9: 0 | AQ9: 0 | AR9: 508.4442 | AS9: 5270.0725 | AT9: 0 | AU9: 0 | AV9: 0 | AW9: 0 | AX9: 0 | AY9: 0 | AZ9: 0 | BA9: 76.5315 | BB9: 0 | BC9: 0 | BD9: 781.3817 | BE9: 0 | BF9: 4739718.4 | BG9: 13484.369 | BH9: 0 | BI9: 0 | BJ9: -109.3009 | BK9: 4739674.5 | BL9: 4753049.6 | BM9: 9492768 | BN9: 0 | BO9: 0 | BP9: 9492768 | BQ9: 9492768
A10: 9 | B10: Perikanan | C10: 0 | D10: 0 | E10: 0 | F10: 0 | G10: 0 | H10: 0 | I10: 0 | J10: 0 | K10: 272957.95 | L10: 0 | M10: 0 | N10: 0 | O10: 0 | P10: 0 | Q10: 5756748.9 | R10: 0 | S10: 0 | T10: 0 | U10: 0 | V10: 0 | W10: 2458.4179 | X10: 0 | Y10: 0 | Z10: 0 | AA10: 0 | AB10: 0 | AC10: 0 | AD10: 11.8705 | AE10: 2265.0765 | AF10: 0 | AG10: 0 | AH10: 0 | AI10: 0 | AJ10: 0 | AK10: 0 | AL10: 0 | AM10: 0 | AN10: 0 | AO10: 0 | AP10: 0 | AQ10: 0 | AR10: 39374.671 | AS10: 1575254.4 | AT10: 0 | AU10: 0 | AV10: 0 | AW10: 0 | AX10: 0 | AY10: 0 | AZ10: 0 | BA10: 7571.2064 | BB10: 34918.311 | BC10: 28159.182 | BD10: 86265.892 | BE10: 0 | BF10: 7805985.9 | BG10: 9869527.7 | BH10: 0 | BI10: 187528.02 | BJ10: -0.094 | BK10: 31153.629 | BL10: 10088209 | BM10: 17894195 | BN10: 0 | BO10: 0 | BP10: 17894195 | BQ10: 17894195
A11: 10 | B11: Pertambangan Minyak, Gas dan Panas Bumi | C11: 1238.2717 | D11: 669.797 | E11: 0 | F11: 0 | G11: 72.2709 | H11: 7477.4959 | I11: 27.4729 | J11: 1536.4911 | K11: 912.5321 | L11: 4356637.5 | M11: 216440.04 | N11: 0 | O11: 8436.8919 | P11: 6614663.3 | Q11: 4760.7047 | R11: 0 | S11: 101.0469 | T11: 0.5741 | U11: 237.4063 | V11: 3531.275 | W11: 3654922.8 | X11: 1306298.8 | Y11: 64002.906 | Z11: 16962.11 | AA11: 17568.855 | AB11: 1.8883 | AC11: 316.2737 | AD11: 87.3169 | AE11: 114.5579 | AF11: 2666792.4 | AG11: 32655.65 | AH11: 155.08 | AI11: 87357.549 | AJ11: 5568.7391 | AK11: 51067.168 | AL11: 1037.5159 | AM11: 5153.9197 | AN11: 1084.0428 | AO11: 627.9786 | AP11: 8840.5841 | AQ11: 1213.7712 | AR11: 308.3228 | AS11: 1066.2199 | AT11: 18496.963 | AU11: 7906.0311 | AV11: 3386.5207 | AW11: 1091.3541 | AX11: 5.793 | AY11: 5216.3839 | AZ11: 745.2094 | BA11: 16849.085 | BB11: 7473.603 | BC11: 569.8059 | BD11: 814.1347 | BE11: 0 | BF11: 19202502 | BG11: 15281.712 | BH11: 0 | BI11: 3897.2928 | BJ11: -942234.48 | BK11: 23199489 | BL11: 22276434 | BM11: 41478936 | BN11: 0 | BO11: 0 | BP11: 41478936 | BQ11: 41478936
A12: 11 | B12: Pertambangan Batubara dan Lignit | C12: 1609.376 | D12: 887.8596 | E12: 0 | F12: 0 | G12: 80.6371 | H12: 9695.4983 | I12: 39.3254 | J12: 2028.0538 | K12: 1255.8834 | L12: 15102.453 | M12: 14561916 | N12: 0 | O12: 6415.7517 | P12: 255683.68 | Q12: 6231.8758 | R12: 0 | S12: 224.7533 | T12: 0.9195 | U12: 383.9508 | V12: 7106.0713 | W12: 27630.009 | X12: 4230.9165 | Y12: 925465.69 | Z12: 5700.0271 | AA12: 43342.461 | AB12: 3.4342 | AC12: 429.2021 | AD12: 116.7421 | AE12: 152.5114 | AF12: 1150651.9 | AG12: 8927.3942 | AH12: 400.1864 | AI12: 58534.298 | AJ12: 7777.3424 | AK12: 70028.321 | AL12: 2380.2239 | AM12: 6690.3735 | AN12: 1407.5425 | AO12: 867.2404 | AP12: 11418.04 | AQ12: 1677.853 | AR12: 465.7081 | AS12: 1595.1114 | AT12: 24741.424 | AU12: 10277.878 | AV12: 4439.2485 | AW12: 1444.4519 | AX12: 7.6785 | AY12: 6890.182 | AZ12: 990.8833 | BA12: 23356.353 | BB12: 10256.791 | BC12: 1079.479 | BD12: 1435.2207 | BE12: 0 | BF12: 17283474 | BG12: 68041.654 | BH12: 0 | BI12: 7284.0225 | BJ12: 360.3494 | BK12: 90059558 | BL12: 90135244 | BM12: 1.0741872e+08 | BN12: 0 | BO12: 0 | BP12: 1.0741872e+08 | BQ12: 1.0741872e+08
A13: 12 | B13: Pertambangan Bijih Logam | C13: 0 | D13: 0 | E13: 0 | F13: 0 | G13: 0 | H13: 0 | I13: 0 | J13: 0 | K13: 0 | L13: 0 | M13: 0 | N13: 0 | O13: 0 | P13: 0 | Q13: 0 | R13: 0 | S13: 0 | T13: 0 | U13: 0 | V13: 0 | W13: 0 | X13: 0 | Y13: 0 | Z13: 0 | AA13: 0 | AB13: 0 | AC13: 0 | AD13: 0 | AE13: 0 | AF13: 0 | AG13: 0 | AH13: 0 | AI13: 0 | AJ13: 0 | AK13: 0 | AL13: 0 | AM13: 0 | AN13: 0 | AO13: 0 | AP13: 0 | AQ13: 0 | AR13: 0 | AS13: 0 | AT13: 0 | AU13: 0 | AV13: 0 | AW13: 0 | AX13: 0 | AY13: 0 | AZ13: 0 | BA13: 0 | BB13: 0 | BC13: 0 | BD13: 0 | BE13: 0 | BF13: 0 | BG13: 0 | BH13: 0 | BI13: 0 | BJ13: 0 | BK13: 0 | BL13: 0 | BM13: 0 | BN13: 0 | BO13: 0 | BP13: 0 | BQ13: 0
... A63: 209 | B63: Nilai Tambah Bruto | C63: 14421722 | D63: 5318349.7 | E63: 8422285.4 | F63: 16306552 | G63: 3091909.9 | H63: 7995588.1 | I63: 1449409.4 | J63: 8352368.3 | K63: 15770320 | L63: 30425435 | M63: 46912449 | N63: 0 | O63: 30071012 | P63: 19994588 | Q63: 58627186 | R63: 1144.2429 | S63: 200226.32 | T63: 1243.8277 | U63: 1004870 | V63: 8070604.8 | W63: 7973084.3 | X63: 12288411 | Y63: 1588842.2 | Z63: 54626.457 | AA63: 638654.93 | AB63: 19485.322 | AC63: 97699.234 | AD63: 177470.54 | AE63: 305483.61 | AF63: 756108.59 | AG63: 123810.07 | AH63: 605713 | AI63: 67207973 | AJ63: 10652542 | AK63: 81154297 | AL63: 1499337.4 | AM63: 6239838.2 | AN63: 418202.82 | AO63: 578770.77 | AP63: 3875508.4 | AQ63: 1463249.5 | AR63: 1563970.3 | AS63: 12404749 | AT63: 21031258 | AU63: 8257685 | AV63: 3359774.4 | AW63: 1584157.4 | AX63: 9744.3905 | AY63: 20580130 | AZ63: 726780.17 | BA63: 16676073 | BB63: 13568094 | BC63: 4065505.7 | BD63: 4426895.7 | BE63: 0 | BF63: 5.8241119e+08 | BG63: 0 | BH63: 0 | BI63: 0 | BJ63: 0 | BK63: 0 | BL63: 0 | BM63: 0 | BN63: 0 | BO63: 0 | BP63: 0 | BQ63: 0
A64: 210 | B64: Total Input | C64: 18628421 | D64: 6978109.2 | E64: 12253207 | F64: 23671076 | G64: 4848450.5 | H64: 13139019 | I64: 2080977.3 | J64: 9492768 | K64: 17894195 | L64: 41478936 | M64: 1.0741872e+08 | N64: 0 | O64: 43718756 | P64: 31753634 | Q64: 1.7515007e+08 | R64: 1823.5637 | S64: 753916.33 | T64: 3100.1638 | U64: 2560600.4 | V64: 23130789 | W64: 23019790 | X64: 42984829 | Y64: 3701881.5 | Z64: 218975.66 | AA64: 1713342 | AB64: 52112.72 | AC64: 1203081.9 | AD64: 417377.69 | AE64: 788474.21 | AF64: 6095669.9 | AG64: 176149.58 | AH64: 1048781.8 | AI64: 1.6958426e+08 | AJ64: 15359154 | AK64: 1.2286002e+08 | AL64: 3589335.5 | AM64: 12403639 | AN64: 1429119.3 | AO64: 1339961.1 | AP64: 10269044 | AQ64: 2537804.7 | AR64: 2537261.5 | AS64: 30319604 | AT64: 33989791 | AU64: 9918604.5 | AV64: 5014105.1 | AW64: 2445888.5 | AX64: 15646.889 | AY64: 25122148 | AZ64: 1287244.8 | BA64: 27014877 | BB64: 19871323 | BC64: 8088689.4 | BD64: 6808496.8 | BE64: 0 | BF64: 1.1281831e+09

Sheet IO_Table_2025(CEK)
A1: Kode | B1: Deskripsi | C1: 1 | D1: 2 | E1: 3 | F1: 4 | G1: 5 | H1: 6 | I1: 7 | J1: 8 | K1: 9 | L1: 10 | M1: 11 | N1: 12 | O1: 13 | P1: 14 | Q1: 15 | R1: 16 | S1: 17 | T1: 18 | U1: 19 | V1: 20 | W1: 21 | X1: 22 | Y1: 23 | Z1: 24 | AA1: 25 | AB1: 26 | AC1: 27 | AD1: 28 | AE1: 29 | AF1: 30 | AG1: 31 | AH1: 32 | AI1: 33 | AJ1: 34 | AK1: 35 | AL1: 36 | AM1: 37 | AN1: 38 | AO1: 39 | AP1: 40 | AQ1: 41 | AR1: 42 | AS1: 43 | AT1: 44 | AU1: 45 | AV1: 46 | AW1: 47 | AX1: 48 | AY1: 49 | AZ1: 50 | BA1: 51 | BB1: 52 | BC1: 53 | BD1: 54 | BE1: 55 | BF1: 180 | BG1: 301 | BH1: 302 | BI1: 303 | BJ1: 304 | BK1: 305 | BL1: 309 | BM1: 310 | BN1: 409 | BO1: 509 | BP1: 600 | BQ1: 700 | BS1: Rasio Total Input Antara thd Total Output Sektoral | BT1: Rasio Ekspor thd Total Output Sektoral | BU1: NTB | BV1: Rasio NTB thd Total Output | BW1: NTB to Kuartil NTB | BX1: Linkage Kuadran | BY1: From | BZ1: To Q1 + NTB VERY LOW | CB1: To Q2 & Q3 + NTB VERY LOW
A2: 1 | B2: Pertanian Tanaman Pangan | C2: 1069045 | D2: 0 | E2: 0 | F2: 0 | G2: 0 | H2: 697.3892 | I2: 0 | J2: 0 | K2: 21452.074 | L2: 0 | M2: 0 | N2: 0 | O2: 0 | P2: 0 | Q2: 16469292 | R2: 0 | S2: 0 | T2: 0 | U2: 0 | V2: 0 | W2: 5192.8969 | X2: 0 | Y2: 2043.1564 | Z2: 0 | AA2: 0 | AB2: 0 | AC2: 0 | AD2: 0 | AE2: 0 | AF2: 0 | AG2: 0 | AH2: 0 | AI2: 0 | AJ2: 0 | AK2: 0 | AL2: 0 | AM2: 0 | AN2: 0 | AO2: 0 | AP2: 0 | AQ2: 0 | AR2: 6373.7154 | AS2: 222413.56 | AT2: 0 | AU2: 0 | AV2: 0 | AW2: 0 | AX2: 0 | AY2: 0 | AZ2: 0 | BA2: 70927.807 | BB2: 5489.5984 | BC2: 7671.5013 | BD2: 34190.168 | BE2: 0 | BF2: 17914789 | BG2: 369043.3 | BH2: 0 | BI2: 0 | BJ2: 73419.347 | BK2: 271170 | BL2: 713632.64 | BM2: 18628421 | BN2: 0 | BO2: 0 | BP2: 18628421 | BQ2: 18628421 | BS2: =IFERROR(BF2/BM2,0) -> 0.96169119 | BT2: =IFERROR(BK2/BM2,0) -> 0.014556789 | BU2: {=TRANSPOSE(C63:BE63)} -> 14421722 | BV2: =IFERROR(BU2/BM2,0) -> 0.77417843 | BW2: {=_xlfn.IFS(BV2>$BV$62,"Very High",BV2>$BV$61,"High",BV2>$BV$60,"Low",BV2<=$BV$60,"Very Low")} -> Very High | BX2: K4 (BL Rendah, FL Rendah)
A3: 2 | B3: Pertanian Tanaman Hortikultura Semusim, Hortikultura Tahunan, dan Lainnya | C3: 0 | D3: 75321.678 | E3: 0 | F3: 0 | G3: 76.1594 | H3: 0 | I3: 0 | J3: 0 | K3: 0 | L3: 0 | M3: 0 | N3: 0 | O3: 0 | P3: 0 | Q3: 1238534 | R3: 0 | S3: 0 | T3: 0 | U3: 0 | V3: 0 | W3: 10570.457 | X3: 6.6199 | Y3: 0 | Z3: 0 | AA3: 0 | AB3: 0 | AC3: 0 | AD3: 19.6128 | AE3: 0 | AF3: 27.5495 | AG3: 0 | AH3: 0 | AI3: 31036.814 | AJ3: 0 | AK3: 0 | AL3: 3636.1612 | AM3: 0 | AN3: 927.9023 | AO3: 0 | AP3: 16386.871 | AQ3: 0 | AR3: 20599.848 | AS3: 541937.3 | AT3: 0.3453 | AU3: 242.0894 | AV3: 0 | AW3: 0 | AX3: 0 | AY3: 0 | AZ3: 0 | BA3: 2170.2044 | BB3: 2348.2498 | BC3: 57539.736 | BD3: 4049.9285 | BE3: 0 | BF3: 2005431.5 | BG3: 4139011 | BH3: 0 | BI3: 179801.13 | BJ3: 52261.44 | BK3: 601604.07 | BL3: 4972677.7 | BM3: 6978109.2 | BN3: 0 | BO3: 0 | BP3: 6978109.2 | BQ3: 6978109.2 | BS3: =IFERROR(BF3/BM3,0) -> 0.28738895 | BT3: =IFERROR(BK3/BM3,0) -> 0.086213049 | BU3: 5318349.7 | BV3: =IFERROR(BU3/BM3,0) -> 0.76214768 | BW3: {=_xlfn.IFS(BV3>$BV$62,"Very High",BV3>$BV$61,"High",BV3>$BV$60,"Low",BV3<=$BV$60,"Very Low")} -> Very High | BX3: K4 (BL Rendah, FL Rendah)
A4: 3 | B4: Karet | C4: 0 | D4: 0 | E4: 1091870 | F4: 0 | G4: 0 | H4: 0 | I4: 0 | J4: 0 | K4: 0 | L4: 0 | M4: 0 | N4: 0 | O4: 0 | P4: 0 | Q4: 0 | R4: 0 | S4: 0 | T4: 0 | U4: 0 | V4: 0 | W4: 0 | X4: 11154452 | Y4: 0 | Z4: 0 | AA4: 0 | AB4: 0 | AC4: 0 | AD4: 0 | AE4: 0 | AF4: 0 | AG4: 0 | AH4: 0 | AI4: 0 | AJ4: 0 | AK4: 6820.7965 | AL4: 0 | AM4: 0 | AN4: 0 | AO4: 0 | AP4: 0 | AQ4: 0 | AR4: 0 | AS4: 0 | AT4: 0 | AU4: 0 | AV4: 0 | AW4: 0 | AX4: 0 | AY4: 0 | AZ4: 0 | BA4: 0 | BB4: 0 | BC4: 0 | BD4: 0 | BE4: 0 | BF4: 12253142 | BG4: 0 | BH4: 0 | BI4: 0 | BJ4: 0 | BK4: 64.5775 | BL4: 64.5775 | BM4: 12253207 | BN4: 0 | BO4: 0 | BP4: 12253207 | BQ4: 12253207 | BS4: =IFERROR(BF4/BM4,0) -> 0.99999473 | BT4: =IFERROR(BK4/BM4,0) -> 5.270253e-06 | BU4: 8422285.4 | BV4: =IFERROR(BU4/BM4,0) -> 0.68735356 | BW4: {=_xlfn.IFS(BV4>$BV$62,"Very High",BV4>$BV$61,"High",BV4>$BV$60,"Low",BV4<=$BV$60,"Very Low")} -> Very High | BX4: K1 (BL Tinggi, FL Tinggi)
A5: 4 | B5: Kelapa Sawit | C5: 0 | D5: 0 | E5: 0 | F5: 2061576.3 | G5: 0 | H5: 0 | I5: 0 | J5: 0 | K5: 0 | L5: 0 | M5: 0 | N5: 0 | O5: 0 | P5: 0 | Q5: 20717828 | R5: 0 | S5: 0 | T5: 0 | U5: 0 | V5: 0 | W5: 0 | X5: 0 | Y5: 0 | Z5: 0 | AA5: 0 | AB5: 0 | AC5: 0 | AD5: 0 | AE5: 0 | AF5: 0 | AG5: 0 | AH5: 0 | AI5: 0 | AJ5: 0 | AK5: 15026.465 | AL5: 0 | AM5: 0 | AN5: 0 | AO5: 0 | AP5: 0 | AQ5: 0 | AR5: 0 | AS5: 0 | AT5: 0 | AU5: 0 | AV5: 0 | AW5: 0 | AX5: 0 | AY5: 0 | AZ5: 0 | BA5: 0 | BB5: 0 | BC5: 0 | BD5: 0 | BE5: 0 | BF5: 22794431 | BG5: 0 | BH5: 0 | BI5: 0 | BJ5: 0 | BK5: 876645.07 | BL5: 876645.07 | BM5: 23671076 | BN5: 0 | BO5: 0 | BP5: 23671076 | BQ5: 23671076 | BS5: =IFERROR(BF5/BM5,0) -> 0.96296556 | BT5: =IFERROR(BK5/BM5,0) -> 0.037034441 | BU5: 16306552 | BV5: =IFERROR(BU5/BM5,0) -> 0.68888092 | BW5: {=_xlfn.IFS(BV5>$BV$62,"Very High",BV5>$BV$61,"High",BV5>$BV$60,"Low",BV5<=$BV$60,"Very Low")} -> Very High | BX5: K3 (BL Rendah, FL Tinggi)
A6: 5 | B6: Tanaman Perkebunan lainnya | C6: 0 | D6: 0 | E6: 0 | F6: 0 | G6: 313476.6 | H6: 0 | I6: 0 | J6: 0 | K6: 0 | L6: 0 | M6: 0 | N6: 0 | O6: 0 | P6: 0 | Q6: 247988.19 | R6: 0 | S6: 0 | T6: 21.748 | U6: 37.7579 | V6: 0 | W6: 766241.01 | X6: 3206.6985 | Y6: 12.9868 | Z6: 0 | AA6: 0 | AB6: 3.6649 | AC6: 0 | AD6: 1969.0134 | AE6: 2189.6912 | AF6: 0 | AG6: 0 | AH6: 0 | AI6: 263.638 | AJ6: 0 | AK6: 0 | AL6: 0 | AM6: 0 | AN6: 0 | AO6: 0 | AP6: 0 | AQ6: 0 | AR6: 87.1216 | AS6: 164973.83 | AT6: 0 | AU6: 0 | AV6: 0 | AW6: 0 | AX6: 0 | AY6: 0 | AZ6: 0 | BA6: 21.8348 | BB6: 117.2845 | BC6: 7811.2873 | BD6: 964.4516 | BE6: 0 | BF6: 1509386.8 | BG6: 172325.96 | BH6: 0 | BI6: 1543475.4 | BJ6: 80904.957 | BK6: 1542357.3 | BL6: 3339063.7 | BM6: 4848450.5 | BN6: 0 | BO6: 0 | BP6: 4848450.5 | BQ6: 4848450.5 | BS6: =IFERROR(BF6/BM6,0) -> 0.31131324 | BT6: =IFERROR(BK6/BM6,0) -> 0.31811346 | BU6: 3091909.9 | BV6: =IFERROR(BU6/BM6,0) -> 0.63771092 | BW6: {=_xlfn.IFS(BV6>$BV$62,"Very High",BV6>$BV$61,"High",BV6>$BV$60,"Low",BV6<=$BV$60,"Very Low")} -> High | BX6: K2 (BL Tinggi, FL Rendah)
A7: 6 | B7: Peternakan | C7: 28631.704 | D7: 61683.885 | E7: 0 | F7: 1085.4154 | G7: 327.8782 | H7: 134988.8 | I7: 6920.5818 | J7: 813.2388 | K7: 168.4107 | L7: 0 | M7: 0 | N7: 0 | O7: 0 | P7: 0 | Q7: 5249641.1 | R7: 0 | S7: 4803.2183 | T7: 22.4412 | U7: 0 | V7: 0 | W7: 433.5162 | X7: 0 | Y7: 0 | Z7: 0 | AA7: 0 | AB7: 0 | AC7: 0 | AD7: 0.0098 | AE7: 0 | AF7: 0 | AG7: 0 | AH7: 0 | AI7: 0 | AJ7: 0 | AK7: 0 | AL7: 0 | AM7: 0 | AN7: 0 | AO7: 0 | AP7: 0 | AQ7: 0 | AR7: 38344.743 | AS7: 683315.58 | AT7: 0 | AU7: 0 | AV7: 0 | AW7: 0 | AX7: 0 | AY7: 0 | AZ7: 0 | BA7: 47729.646 | BB7: 13354.979 | BC7: 41265.269 | BD7: 32619.371 | BE7: 0 | BF7: 6346149.8 | BG7: 2947885.3 | BH7: 0 | BI7: 3614047.6 | BJ7: 198195.78 | BK7: 32740.831 | BL7: 6792869.5 | BM7: 13139019 | BN7: 0 | BO7: 0 | BP7: 13139019 | BQ7: 13139019 | BS7: =IFERROR(BF7/BM7,0) -> 0.48300026 | BT7: =IFERROR(BK7/BM7,0) -> 0.0024918779 | BU7: 7995588.1 | BV7: =IFERROR(BU7/BM7,0) -> 0.60853766 | BW7: {=_xlfn.IFS(BV7>$BV$62,"Very High",BV7>$BV$61,"High",BV7>$BV$60,"Low",BV7<=$BV$60,"Very Low")} -> High | BX7: K4 (BL Rendah, FL Rendah)
A8: 7 | B8: Jasa Pertanian dan Perburuan | C8: 197662.84 | D8: 51424.309 | E8: 0 | F8: 1041080.8 | G8: 779061.32 | H8: 0 | I8: 0 | J8: 0 | K8: 0 | L8: 0 | M8: 0 | N8: 0 | O8: 0 | P8: 0 | Q8: 0 | R8: 0 | S8: 0 | T8: 0 | U8: 0 | V8: 0 | W8: 0 | X8: 0 | Y8: 0 | Z8: 0 | AA8: 0 | AB8: 0 | AC8: 0 | AD8: 0 | AE8: 0 | AF8: 0 | AG8: 0 | AH8: 0 | AI8: 0 | AJ8: 0 | AK8: 0 | AL8: 0 | AM8: 0 | AN8: 0 | AO8: 0 | AP8: 0 | AQ8: 0 | AR8: 0 | AS8: 0 | AT8: 0 | AU8: 0 | AV8: 0 | AW8: 0 | AX8: 0 | AY8: 0 | AZ8: 0 | BA8: 7224.8618 | BB8: 0 | BC8: 0 | BD8: 0 | BE8: 0 | BF8: 2076454.1 | BG8: 4523.2212 | BH8: 0 | BI8: 0 | BJ8: 0 | BK8: 0 | BL8: 4523.2212 | BM8: 2080977.3 | BN8: 0 | BO8: 0 | BP8: 2080977.3 | BQ8: 2080977.3 | BS8: =IFERROR(BF8/BM8,0) -> 0.9978264 | BT8: =IFERROR(BK8/BM8,0) -> 0 | BU8: 1449409.4 | BV8: =IFERROR(BU8/BM8,0) -> 0.69650415 | BW8: {=_xlfn.IFS(BV8>$BV$62,"Very High",BV8>$BV$61,"High",BV8>$BV$60,"Low",BV8<=$BV$60,"Very Low")} -> Very High | BX8: K2 (BL Tinggi, FL Rendah)
A9: 8 | B9: Kehutanan dan Penebangan Kayu | C9: 1.0454 | D9: 620.0298 | E9: 0 | F9: 19104.265 | G9: 1560.9711 | H9: 6494.6021 | I9: 2.0291 | J9: 119124.84 | K9: 678.5901 | L9: 0 | M9: 33769.315 | N9: 0 | O9: 5412.3937 | P9: 1432.2475 | Q9: 80449.067 | R9: 0 | S9: 3094.5964 | T9: 2.9143 | U9: 571531.65 | V9: 669693.81 | W9: 35875.712 | X9: 12354.974 | Y9: 132.0165 | Z9: 0.3821 | AA9: 66.4564 | AB9: 0 | AC9: 254.7084 | AD9: 3400.5184 | AE9: 3163.057 | AF9: 0 | AG9: 0 | AH9: 0 | AI9: 3160108.9 | AJ9: 3260.6437 | AK9: 1492.2123 | AL9: 0 | AM9: 0 | AN9: 0 | AO9: 0 | AP9: 0 | AQ9: 0 | AR9: 508.4442 | AS9: 5270.0725 | AT9: 0 | AU9: 0 | AV9: 0 | AW9: 0 | AX9: 0 | AY9: 0 | AZ9: 0 | BA9: 76.5315 | BB9: 0 | BC9: 0 | BD9: 781.3817 | BE9: 0 | BF9: 4739718.4 | BG9: 13484.369 | BH9: 0 | BI9: 0 | BJ9: -109.3009 | BK9: 4739674.5 | BL9: 4753049.6 | BM9: 9492768 | BN9: 0 | BO9: 0 | BP9: 9492768 | BQ9: 9492768 | BS9: =IFERROR(BF9/BM9,0) -> 0.49929783 | BT9: =IFERROR(BK9/BM9,0) -> 0.4992932 | BU9: 8352368.3 | BV9: =IFERROR(BU9/BM9,0) -> 0.87986647 | BW9: {=_xlfn.IFS(BV9>$BV$62,"Very High",BV9>$BV$61,"High",BV9>$BV$60,"Low",BV9<=$BV$60,"Very Low")} -> Very High | BX9: K4 (BL Rendah, FL Rendah) | BY9: 8 | BZ9: 20 | CA9: 19
A10: 9 | B10: Perikanan | C10: 0 | D10: 0 | E10: 0 | F10: 0 | G10: 0 | H10: 0 | I10: 0 | J10: 0 | K10: 272957.95 | L10: 0 | M10: 0 | N10: 0 | O10: 0 | P10: 0 | Q10: 5756748.9 | R10: 0 | S10: 0 | T10: 0 | U10: 0 | V10: 0 | W10: 2458.4179 | X10: 0 | Y10: 0 | Z10: 0 | AA10: 0 | AB10: 0 | AC10: 0 | AD10: 11.8705 | AE10: 2265.0765 | AF10: 0 | AG10: 0 | AH10: 0 | AI10: 0 | AJ10: 0 | AK10: 0 | AL10: 0 | AM10: 0 | AN10: 0 | AO10: 0 | AP10: 0 | AQ10: 0 | AR10: 39374.671 | AS10: 1575254.4 | AT10: 0 | AU10: 0 | AV10: 0 | AW10: 0 | AX10: 0 | AY10: 0 | AZ10: 0 | BA10: 7571.2064 | BB10: 34918.311 | BC10: 28159.182 | BD10: 86265.892 | BE10: 0 | BF10: 7805985.9 | BG10: 9869527.7 | BH10: 0 | BI10: 187528.02 | BJ10: -0.094 | BK10: 31153.629 | BL10: 10088209 | BM10: 17894195 | BN10: 0 | BO10: 0 | BP10: 17894195 | BQ10: 17894195 | BS10: =IFERROR(BF10/BM10,0) -> 0.43623006 | BT10: =IFERROR(BK10/BM10,0) -> 0.0017409908 | BU10: 15770320 | BV10: =IFERROR(BU10/BM10,0) -> 0.88130927 | BW10: {=_xlfn.IFS(BV10>$BV$62,"Very High",BV10>$BV$61,"High",BV10>$BV$60,"Low",BV10<=$BV$60,"Very Low")} -> Very High | BX10: K4 (BL Rendah, FL Rendah) | BY10: 9 | BZ10: 15
A11: 10 | B11: Pertambangan Minyak, Gas dan Panas Bumi | C11: 1238.2717 | D11: 669.797 | E11: 0 | F11: 0 | G11: 72.2709 | H11: 7477.4959 | I11: 27.4729 | J11: 1536.4911 | K11: 912.5321 | L11: 4356637.5 | M11: 216440.04 | N11: 0 | O11: 8436.8919 | P11: 6614663.3 | Q11: 4760.7047 | R11: 0 | S11: 101.0469 | T11: 0.5741 | U11: 237.4063 | V11: 3531.275 | W11: 3654922.8 | X11: 1306298.8 | Y11: 64002.906 | Z11: 16962.11 | AA11: 17568.855 | AB11: 1.8883 | AC11: 316.2737 | AD11: 87.3169 | AE11: 114.5579 | AF11: 2666792.4 | AG11: 32655.65 | AH11: 155.08 | AI11: 87357.549 | AJ11: 5568.7391 | AK11: 51067.168 | AL11: 1037.5159 | AM11: 5153.9197 | AN11: 1084.0428 | AO11: 627.9786 | AP11: 8840.5841 | AQ11: 1213.7712 | AR11: 308.3228 | AS11: 1066.2199 | AT11: 18496.963 | AU11: 7906.0311 | AV11: 3386.5207 | AW11: 1091.3541 | AX11: 5.793 | AY11: 5216.3839 | AZ11: 745.2094 | BA11: 16849.085 | BB11: 7473.603 | BC11: 569.8059 | BD11: 814.1347 | BE11: 0 | BF11: 19202502 | BG11: 15281.712 | BH11: 0 | BI11: 3897.2928 | BJ11: -942234.48 | BK11: 23199489 | BL11: 22276434 | BM11: 41478936 | BN11: 0 | BO11: 0 | BP11: 41478936 | BQ11: 41478936 | BS11: =IFERROR(BF11/BM11,0) -> 0.46294588 | BT11: =IFERROR(BK11/BM11,0) -> 0.55930772 | BU11: 30425435 | BV11: =IFERROR(BU11/BM11,0) -> 0.73351531 | BW11: {=_xlfn.IFS(BV11>$BV$62,"Very High",BV11>$BV$61,"High",BV11>$BV$60,"Low",BV11<=$BV$60,"Very Low")} -> Very High | BX11: K3 (BL Rendah, FL Tinggi)
A12: 11 | B12: Pertambangan Batubara dan Lignit | C12: 1609.376 | D12: 887.8596 | E12: 0 | F12: 0 | G12: 80.6371 | H12: 9695.4983 | I12: 39.3254 | J12: 2028.0538 | K12: 1255.8834 | L12: 15102.453 | M12: 14561916 | N12: 0 | O12: 6415.7517 | P12: 255683.68 | Q12: 6231.8758 | R12: 0 | S12: 224.7533 | T12: 0.9195 | U12: 383.9508 | V12: 7106.0713 | W12: 27630.009 | X12: 4230.9165 | Y12: 925465.69 | Z12: 5700.0271 | AA12: 43342.461 | AB12: 3.4342 | AC12: 429.2021 | AD12: 116.7421 | AE12: 152.5114 | AF12: 1150651.9 | AG12: 8927.3942 | AH12: 400.1864 | AI12: 58534.298 | AJ12: 7777.3424 | AK12: 70028.321 | AL12: 2380.2239 | AM12: 6690.3735 | AN12: 1407.5425 | AO12: 867.2404 | AP12: 11418.04 | AQ12: 1677.853 | AR12: 465.7081 | AS12: 1595.1114 | AT12: 24741.424 | AU12: 10277.878 | AV12: 4439.2485 | AW12: 1444.4519 | AX12: 7.6785 | AY12: 6890.182 | AZ12: 990.8833 | BA12: 23356.353 | BB12: 10256.791 | BC12: 1079.479 | BD12: 1435.2207 | BE12: 0 | BF12: 17283474 | BG12: 68041.654 | BH12: 0 | BI12: 7284.0225 | BJ12: 360.3494 | BK12: 90059558 | BL12: 90135244 | BM12: 1.0741872e+08 | BN12: 0 | BO12: 0 | BP12: 1.0741872e+08 | BQ12: 1.0741872e+08 | BS12: =IFERROR(BF12/BM12,0) -> 0.16089816 | BT12: =IFERROR(BK12/BM12,0) -> 0.83839725 | BU12: 46912449 | BV12: =IFERROR(BU12/BM12,0) -> 0.43672508 | BW12: {=_xlfn.IFS(BV12>$BV$62,"Very High",BV12>$BV$61,"High",BV12>$BV$60,"Low",BV12<=$BV$60,"Very Low")} -> Low | BX12: K1 (BL Tinggi, FL Tinggi)
A13: 12 | B13: Pertambangan Bijih Logam | C13: 0 | D13: 0 | E13: 0 | F13: 0 | G13: 0 | H13: 0 | I13: 0 | J13: 0 | K13: 0 | L13: 0 | M13: 0 | N13: 0 | O13: 0 | P13: 0 | Q13: 0 | R13: 0 | S13: 0 | T13: 0 | U13: 0 | V13: 0 | W13: 0 | X13: 0 | Y13: 0 | Z13: 0 | AA13: 0 | AB13: 0 | AC13: 0 | AD13: 0 | AE13: 0 | AF13: 0 | AG13: 0 | AH13: 0 | AI13: 0 | AJ13: 0 | AK13: 0 | AL13: 0 | AM13: 0 | AN13: 0 | AO13: 0 | AP13: 0 | AQ13: 0 | AR13: 0 | AS13: 0 | AT13: 0 | AU13: 0 | AV13: 0 | AW13: 0 | AX13: 0 | AY13: 0 | AZ13: 0 | BA13: 0 | BB13: 0 | BC13: 0 | BD13: 0 | BE13: 0 | BF13: 0 | BG13: 0 | BH13: 0 | BI13: 0 | BJ13: 0 | BK13: 0 | BL13: 0 | BM13: 0 | BN13: 0 | BO13: 0 | BP13: 0 | BQ13: 0 | BS13: =IFERROR(BF13/BM13,0) -> 0 | BT13: =IFERROR(BK13/BM13,0) -> 0 | BU13: 0 | BV13: =IFERROR(BU13/BM13,0) -> 0 | BW13: {=_xlfn.IFS(BV13>$BV$62,"Very High",BV13>$BV$61,"High",BV13>$BV$60,"Low",BV13<=$BV$60,"Very Low")} -> Very Low | BX13: K4 (BL Rendah, FL Rendah)
A14: 13 | B14: Pertambangan dan Penggalian Lainnya | C14: 360.8562 | D14: 159.7603 | E14: 0 | F14: 0 | G14: 70.6754 | H14: 1458.6068 | I14: 5.9931 | J14: 380.3576 | K14: 189.708 | L14: 380268.49 | M14: 10404147 | N14: 0 | O14: 667255.89 | P14: 1042.0417 | Q14: 177338.58 | R14: 0 | S14: 19.3571 | T14: 1.2859 | U14: 122.6122 | V14: 680.1209 | W14: 616010.58 | X14: 18784.902 | Y14: 244095.81 | Z14: 146.8797 | AA14: 1831.7573 | AB14: 1.9574 | AC14: 194.5053 | AD14: 1172.2147 | AE14: 6568.9539 | AF14: 8534.7502 | AG14: 2.8187 | AH14: 35.8943 | AI14: 8404859.7 | AJ14: 1100.4534 | AK14: 10449.344 | AL14: 249.563 | AM14: 976.7732 | AN14: 214.3265 | AO14: 124.7097 | AP14: 1675.538 | AQ14: 279.1346 | AR14: 62.2424 | AS14: 208.9178 | AT14: 3633.8739 | AU14: 1521.787 | AV14: 648.9453 | AW14: 208.6282 | AX14: 1.1165 | AY14: 1416.9904 | AZ14: 142.9683 | BA14: 3590.1449 | BB14: 1449.3511 | BC14: 112.7254 | BD14: 162.9144 | BE14: 0 | BF14: 20963973 | BG14: 54146.789 | BH14: 0 | BI14: 272877.44 | BJ14: 1451.3202 | BK14: 22426308 | BL14: 22754784 | BM14: 43718756 | BN14: 0 | BO14: 0 | BP14: 43718756 | BQ14: 43718756 | BS14: =IFERROR(BF14/BM14,0) -> 0.47951896 | BT14: =IFERROR(BK14/BM14,0) -> 0.51296766 | BU14: 30071012 | BV14: =IFERROR(BU14/BM14,0) -> 0.68782863 | BW14: {=_xlfn.IFS(BV14>$BV$62,"Very High",BV14>$BV$61,"High",BV14>$BV$60,"Low",BV14<=$BV$60,"Very Low")} -> Very High | BX14: K3 (BL Rendah, FL Tinggi)
A15: 14 | B15: Industri Batubara dan Pengilangan Migas | C15: 13011.016 | D15: 14614.407 | E15: 0 | F15: 0 | G15: 1417.0359 | H15: 939395.98 | I15: 994.783 | J15: 129319.14 | K15: 275077.96 | L15: 86679.045 | M15: 2971054.7 | N15: 0 | O15: 1451393.5 | P15: 117704.57 | Q15: 257561.13 | R15: 0 | S15: 14820.735 | T15: 50.2062 | U15: 27085.625 | V15: 499123.95 | W15: 278410.16 | X15: 194572.28 | Y15: 48746.256 | Z15: 2689.4906 | AA15: 7698.8211 | AB15: 40.0303 | AC15: 11199.248 | AD15: 3036.7421 | AE15: 8805.4999 | AF15: 20649.46 | AG15: 4318.1692 | AH15: 4178.5751 | AI15: 6805168 | AJ15: 386532.75 | AK15: 6396859.2 | AL15: 318281.81 | AM15: 2955506.4 | AN15: 347114.81 | AO15: 241243.03 | AP15: 2174532.1 | AQ15: 31362.454 | AR15: 5558.871 | AS15: 62476.234 | AT15: 64794.065 | AU15: 4404.3282 | AV15: 2977.3726 | AW15: 38.3875 | AX15: 21.764 | AY15: 77178.405 | AZ15: 35936.278 | BA15: 31172.44 | BB15: 53718.102 | BC15: 49094.978 | BD15: 121352.15 | BE15: 0 | BF15: 27548972 | BG15: 2407676.4 | BH15: 0 | BI15: 0 | BJ15: 276611.21 | BK15: 1520373.9 | BL15: 4204661.5 | BM15: 31753634 | BN15: 0 | BO15: 0 | BP15: 31753634 | BQ15: 31753634 | BS15: =IFERROR(BF15/BM15,0) -> 0.86758487 | BT15: =IFERROR(BK15/BM15,0) -> 0.047880313 | BU15: 19994588 | BV15: =IFERROR(BU15/BM15,0) -> 0.62967872 | BW15: {=_xlfn.IFS(BV15>$BV$62,"Very High",BV15>$BV$61,"High",BV15>$BV$60,"Low",BV15<=$BV$60,"Very Low")} -> High | BX15: K3 (BL Rendah, FL Tinggi)
A16: 15 | B16: Industri Makanan dan Minuman | C16: 368.2422 | D16: 308.6413 | E16: 240784.53 | F16: 662172.57 | G16: 31138.15 | H16: 453910.18 | I16: 465058.22 | J16: 1300.3688 | K16: 562262.43 | L16: 35451.951 | M16: 211992.56 | N16: 0 | O16: 1372.573 | P16: 10958.384 | Q16: 32080693 | R16: 0.0585 | S16: 9935.6038 | T16: 313.7861 | U16: 12129.835 | V16: 54081.446 | W16: 482018.23 | X16: 17686.732 | Y16: 3360.8814 | Z16: 328.1037 | AA16: 2093.1381 | AB16: 37.1839 | AC16: 2762.4521 | AD16: 1501.2157 | AE16: 2088.2549 | AF16: 2411.1389 | AG16: 280.6258 | AH16: 6295.7769 | AI16: 116700.22 | AJ16: 17531.675 | AK16: 189384.77 | AL16: 10506.926 | AM16: 1072.385 | AN16: 101714.19 | AO16: 24864.517 | AP16: 220286.64 | AQ16: 10570.139 | AR16: 454122.85 | AS16: 8953330 | AT16: 26974.256 | AU16: 33781.829 | AV16: 39065.918 | AW16: 2158.4995 | AX16: 42.5307 | AY16: 18460.508 | AZ16: 4031.3514 | BA16: 734055 | BB16: 742338.05 | BC16: 822693.21 | BD16: 209068.94 | BE16: 0 | BF16: 48087850 | BG16: 89427004 | BH16: 1040496.1 | BI16: 12103.788 | BJ16: -1737523.8 | BK16: 38320141 | BL16: 1.2706222e+08 | BM16: 1.7515007e+08 | BN16: 0 | BO16: 0 | BP16: 1.7515007e+08 | BQ16: 1.7515007e+08 | BS16: =IFERROR(BF16/BM16,0) -> 0.27455227 | BT16: =IFERROR(BK16/BM16,0) -> 0.21878461 | BU16: 58627186 | BV16: =IFERROR(BU16/BM16,0) -> 0.33472545 | BW16: {=_xlfn.IFS(BV16>$BV$62,"Very High",BV16>$BV$61,"High",BV16>$BV$60,"Low",BV16<=$BV$60,"Very Low")} -> Very Low | BX16: K1 (BL Tinggi, FL Tinggi)
A17: 16 | B17: Industri Pengolahan Tembakau | C17: 1.6156 | D17: 0.8725 | E17: 0 | F17: 0 | G17: 7.019 | H17: 9.7298 | I17: 0.0355 | J17: 2.0025 | K17: 137.1405 | L17: 12.9007 | M17: 211.4131 | N17: 0 | O17: 6.4743 | P17: 1.733 | Q17: 4.999 | R17: 1.6442 | S17: 0.1357 | T17: 0 | U17: 0.3115 | V17: 4.595 | W17: 1.3223 | X17: 2.976 | Y17: 0.5623 | Z17: 0.0176 | AA17: 0.2266 | AB17: 0 | AC17: 0.4085 | AD17: 0.1081 | AE17: 0.1035 | AF17: 3.7221 | AG17: 0.0157 | AH17: 0.2028 | AI17: 56.8641 | AJ17: 7.2451 | AK17: 66.4245 | AL17: 1.3409 | AM17: 6.7074 | AN17: 1.4119 | AO17: 0.8168 | AP17: 11.4933 | AQ17: 1.5765 | AR17: 0.4037 | AS17: 1.3894 | AT17: 24.0591 | AU17: 10.281 | AV17: 4.4018 | AW17: 1.4191 | AX17: 0.0103 | AY17: 6.7884 | AZ17: 0.9685 | BA17: 21.9182 | BB17: 9.7251 | BC17: 0.737 | BD17: 1.4676 | BE17: 0 | BF17: 649.7372 | BG17: 1170.7477 | BH17: 0 | BI17: 3.4097 | BJ17: -0.3309 | BK17: 0 | BL17: 1173.8265 | BM17: 1823.5637 | BN17: 0 | BO17: 0 | BP17: 1823.5637 | BQ17: 1823.5637 | BS17: =IFERROR(BF17/BM17,0) -> 0.3563008 | BT17: =IFERROR(BK17/BM17,0) -> 0 | BU17: 1144.2429 | BV17: =IFERROR(BU17/BM17,0) -> 0.62747624 | BW17: {=_xlfn.IFS(BV17>$BV$62,"Very High",BV17>$BV$61,"High",BV17>$BV$60,"Low",BV17<=$BV$60,"Very Low")} -> High | BX17: K4 (BL Rendah, FL Rendah)
A18: 17 | B18: Industri Tekstil dan Pakaian Jadi | C18: 1834.211 | D18: 3849.7432 | E18: 97729.304 | F18: 3984.1409 | G18: 269.1111 | H18: 2281.9532 | I18: 1.5659 | J18: 223.6916 | K18: 324.5303 | L18: 322.3216 | M18: 4010.9443 | N18: 0 | O18: 66.9041 | P18: 0.7693 | Q18: 1920.4453 | R18: 0 | S18: 24650.49 | T18: 6.2895 | U18: 263.0337 | V18: 1982.6155 | W18: 1463.1141 | X18: 8424.3177 | Y18: 53.0908 | Z18: 0.4255 | AA18: 135.3258 | AB18: 0.1031 | AC18: 30.0848 | AD18: 975.3401 | AE18: 227.1929 | AF18: 0.3443 | AG18: 0.6012 | AH18: 26.1032 | AI18: 13612.068 | AJ18: 3893.4631 | AK18: 23477.845 | AL18: 0.266 | AM18: 10.2404 | AN18: 30.2146 | AO18: 0.2233 | AP18: 9.7319 | AQ18: 219.9806 | AR18: 509.9314 | AS18: 319.0151 | AT18: 350.9328 | AU18: 917.6598 | AV18: 112.9403 | AW18: 27.9646 | AX18: 0.1616 | AY18: 647.5789 | AZ18: 93.7883 | BA18: 3885.55 | BB18: 5112.4103 | BC18: 8581.0634 | BD18: 9499.6528 | BE18: 0 | BF18: 226370.79 | BG18: 497705.14 | BH18: 0 | BI18: 24504.428 | BJ18: 653.944 | BK18: 4682.0374 | BL18: 527545.54 | BM18: 753916.33 | BN18: 0 | BO18: 0 | BP18: 753916.33 | BQ18: 753916.33 | BS18: =IFERROR(BF18/BM18,0) -> 0.30025983 | BT18: =IFERROR(BK18/BM18,0) -> 0.0062102878 | BU18: 200226.32 | BV18: =IFERROR(BU18/BM18,0) -> 0.26558162 | BW18: {=_xlfn.IFS(BV18>$BV$62,"Very High",BV18>$BV$61,"High",BV18>$BV$60,"Low",BV18<=$BV$60,"Very Low")} -> Very Low | BX18: K2 (BL Tinggi, FL Rendah)
A19: 18 | B19: Industri Kulit, Barang dari Kulit dan Alas Kaki | C19: 0 | D19: 0 | E19: 0 | F19: 0 | G19: 0 | H19: 0 | I19: 0 | J19: 0 | K19: 0 | L19: 0 | M19: 0 | N19: 0 | O19: 0 | P19: 0 | Q19: 46.0266 | R19: 0 | S19: 0 | T19: 0 | U19: 0 | V19: 0 | W19: 0 | X19: 0 | Y19: 0 | Z19: 0 | AA19: 0 | AB19: 0 | AC19: 0 | AD19: 25.0566 | AE19: 0 | AF19: 0 | AG19: 0 | AH19: 30.8165 | AI19: 0 | AJ19: 0 | AK19: 0 | AL19: 0 | AM19: 0 | AN19: 0 | AO19: 0 | AP19: 0 | AQ19: 0 | AR19: 0 | AS19: 3.9922 | AT19: 0 | AU19: 0 | AV19: 0 | AW19: 0 | AX19: 0 | AY19: 0 | AZ19: 0 | BA19: 0 | BB19: 0 | BC19: 0 | BD19: 0 | BE19: 0 | BF19: 105.892 | BG19: 3066.1263 | BH19: 0 | BI19: 0 | BJ19: -71.8545 | BK19: 0 | BL19: 2994.2719 | BM19: 3100.1638 | BN19: 0 | BO19: 0 | BP19: 3100.1638 | BQ19: 3100.1638 | BS19: =IFERROR(BF19/BM19,0) -> 0.034156905 | BT19: =IFERROR(BK19/BM19,0) -> 0 | BU19: 1243.8277 | BV19: =IFERROR(BU19/BM19,0) -> 0.40121354 | BW19: {=_xlfn.IFS(BV19>$BV$62,"Very High",BV19>$BV$61,"High",BV19>$BV$60,"Low",BV19<=$BV$60,"Very Low")} -> Low | BX19: K2 (BL Tinggi, FL Rendah)
A20: 19 | B20: Industri Kayu, Barang dari Kayu dan Gabus dan Barang Anyaman dari Bambu, Rotan dan Sejenisnya | C20: 377.1349 | D20: 492.3282 | E20: 47128.184 | F20: 0 | G20: 156.9949 | H20: 2989.4806 | I20: 59.8979 | J20: 226.2498 | K20: 267.5592 | L20: 592.5242 | M20: 11243.155 | N20: 0 | O20: 1779.1309 | P20: 132.9508 | Q20: 11146.903 | R20: 0.0495 | S20: 75.1778 | T20: 0.2716 | U20: 7746.6572 | V20: 2585.4065 | W20: 1423.0655 | X20: 3192.6169 | Y20: 161.9819 | Z20: 11.9296 | AA20: 203.2209 | AB20: 5.3222 | AC20: 359.154 | AD20: 1715.0416 | AE20: 2254.4493 | AF20: 189.5605 | AG20: 1.7412 | AH20: 36.3861 | AI20: 326633.72 | AJ20: 868.9926 | AK20: 17723.163 | AL20: 145.7689 | AM20: 1023.914 | AN20: 116.8515 | AO20: 99.4256 | AP20: 1098.4478 | AQ20: 101.5845 | AR20: 116.0946 | AS20: 2183.3676 | AT20: 1606.5071 | AU20: 446.4004 | AV20: 214.4072 | AW20: 67.8834 | AX20: 0.3559 | AY20: 386.1273 | AZ20: 74.8051 | BA20: 1307.9277 | BB20: 867.8005 | BC20: 424.349 | BD20: 838.9371 | BE20: 0 | BF20: 452901.35 | BG20: 37725.88 | BH20: 75.3007 | BI20: 8188.7044 | BJ20: 12559.031 | BK20: 2049150.2 | BL20: 2107699.1 | BM20: 2560600.4 | BN20: 0 | BO20: 0 | BP20: 2560600.4 | BQ20: 2560600.4 | BS20: =IFERROR(BF20/BM20,0) -> 0.17687311 | BT20: =IFERROR(BK20/BM20,0) -> 0.80026159 | BU20: 1004870 | BV20: =IFERROR(BU20/BM20,0) -> 0.39243528 | BW20: {=_xlfn.IFS(BV20>$BV$62,"Very High",BV20>$BV$61,"High",BV20>$BV$60,"Low",BV20<=$BV$60,"Very Low")} -> Low | BX20: K2 (BL Tinggi, FL Rendah)
A21: 20 | B21: Industri Kertas dan Barang dari Kertas, Percetakan dan Reproduksi Media Rekaman | C21: 4758.9004 | D21: 13043.763 | E21: 7898.4745 | F21: 0 | G21: 249.643 | H21: 53649.425 | I21: 332.4787 | J21: 1769.565 | K21: 1371.0252 | L21: 68016.453 | M21: 668742.65 | N21: 0 | O21: 17807.513 | P21: 877.6048 | Q21: 109608.59 | R21: 0.2622 | S21: 1891.5614 | T21: 11.0252 | U21: 2369.0777 | V21: 4245575.4 | W21: 21645.177 | X21: 74508.036 | Y21: 4932.2438 | Z21: 195.4894 | AA21: 5171.863 | AB21: 33.8463 | AC21: 2506.484 | AD21: 2144.785 | AE21: 1580.3705 | AF21: 736.4548 | AG21: 39.0147 | AH21: 397.1761 | AI21: 496958.32 | AJ21: 111983.16 | AK21: 1522752.4 | AL21: 4988.8618 | AM21: 6794.0903 | AN21: 1348.9532 | AO21: 2912.0349 | AP21: 6493.0768 | AQ21: 3366.8586 | AR21: 2458.6165 | AS21: 17360.759 | AT21: 606775.48 | AU21: 38297.137 | AV21: 58975.188 | AW21: 12648.477 | AX21: 83.3367 | AY21: 46648.84 | AZ21: 12248.258 | BA21: 247691.6 | BB21: 363484.27 | BC21: 16962.033 | BD21: 25748.462 | BE21: 0 | BF21: 8918844.5 | BG21: 672909.89 | BH21: 477.8845 | BI21: 50536.097 | BJ21: -26134.64 | BK21: 13514155 | BL21: 14211944 | BM21: 23130789 | BN21: 0 | BO21: 0 | BP21: 23130789 | BQ21: 23130789 | BS21: =IFERROR(BF21/BM21,0) -> 0.38558324 | BT21: =IFERROR(BK21/BM21,0) -> 0.58424964 | BU21: 8070604.8 | BV21: =IFERROR(BU21/BM21,0) -> 0.34891179 | BW21: {=_xlfn.IFS(BV21>$BV$62,"Very High",BV21>$BV$61,"High",BV21>$BV$60,"Low",BV21<=$BV$60,"Very Low")} -> Very Low | BX21: K1 (BL Tinggi, FL Tinggi)
A22: 21 | B22: Industri Kimia, Farmasi dan Obat Tradisional | C22: 957501.07 | D22: 546843.33 | E22: 1127093.9 | F22: 782024.38 | G22: 89396.003 | H22: 363329.77 | I22: 10478.263 | J22: 3741.3075 | K22: 28140.389 | L22: 12925.105 | M22: 1256898.2 | N22: 0 | O22: 1599262.2 | P22: 11472.095 | Q22: 897181.37 | R22: 0 | S22: 121661.93 | T22: 325.0499 | U22: 135031.56 | V22: 1259900.1 | W22: 2580316.7 | X22: 3760631.9 | Y22: 161631.18 | Z22: 17328.85 | AA22: 90532.74 | AB22: 266.6421 | AC22: 20230.09 | AD22: 27295.719 | AE22: 59167.207 | AF22: 15919.232 | AG22: 27.6115 | AH22: 134386.03 | AI22: 1678166.2 | AJ22: 87302.806 | AK22: 552438.41 | AL22: 11793.779 | AM22: 21932.829 | AN22: 7070.5446 | AO22: 10067.032 | AP22: 6183.5973 | AQ22: 3940.6899 | AR22: 10746.002 | AS22: 29437.505 | AT22: 98427.688 | AU22: 19300.105 | AV22: 25775.026 | AW22: 5065.9731 | AX22: 17.3318 | AY22: 37931.776 | AZ22: 12753.042 | BA22: 177684.83 | BB22: 407259.36 | BC22: 990332.67 | BD22: 288369.8 | BE22: 0 | BF22: 20552937 | BG22: 2187241.4 | BH22: 1.4789 | BI22: 1120.635 | BJ22: -76777.913 | BK22: 355267.25 | BL22: 2466852.9 | BM22: 23019790 | BN22: 0 | BO22: 0 | BP22: 23019790 | BQ22: 23019790 | BS22: =IFERROR(BF22/BM22,0) -> 0.89283773 | BT22: =IFERROR(BK22/BM22,0) -> 0.015433123 | BU22: 7973084.3 | BV22: =IFERROR(BU22/BM22,0) -> 0.34635782 | BW22: {=_xlfn.IFS(BV22>$BV$62,"Very High",BV22>$BV$61,"High",BV22>$BV$60,"Low",BV22<=$BV$60,"Very Low")} -> Very Low | BX22: K1 (BL Tinggi, FL Tinggi)
... A56: 55 | B56: Sektor lain yang tidak jelas batasannya | C56: 0 | D56: 0 | E56: 0 | F56: 0 | G56: 0 | H56: 0 | I56: 0 | J56: 0 | K56: 0 | L56: 0 | M56: 0 | N56: 0 | O56: 0 | P56: 0 | Q56: 0 | R56: 0 | S56: 0 | T56: 0 | U56: 0 | V56: 0 | W56: 0 | X56: 0 | Y56: 0 | Z56: 0 | AA56: 0 | AB56: 0 | AC56: 0 | AD56: 0 | AE56: 0 | AF56: 0 | AG56: 0 | AH56: 0 | AI56: 0 | AJ56: 0 | AK56: 0 | AL56: 0 | AM56: 0 | AN56: 0 | AO56: 0 | AP56: 0 | AQ56: 0 | AR56: 0 | AS56: 0 | AT56: 0 | AU56: 0 | AV56: 0 | AW56: 0 | AX56: 0 | AY56: 0 | AZ56: 0 | BA56: 0 | BB56: 0 | BC56: 0 | BD56: 0 | BE56: 0 | BF56: 0 | BG56: 0 | BH56: 0 | BI56: 0 | BJ56: 0 | BK56: 0 | BL56: 0 | BM56: 0 | BN56: 0 | BO56: 0 | BP56: 0 | BQ56: 0 | BS56: =IFERROR(BF56/BM56,0) -> 0 | BT56: =IFERROR(BK56/BM56,0) -> 0 | BU56: 0 | BV56: =IFERROR(BU56/BM56,0) -> 0 | BW56: {=_xlfn.IFS(BV56>$BV$62,"Very High",BV56>$BV$61,"High",BV56>$BV$60,"Low",BV56<=$BV$60,"Very Low")} -> Very Low | BX56: K4 (BL Rendah, FL Rendah)
A57: 190 | B57: Input Antara | C57: 3415493.3 | D57: 1284743.8 | E57: 3820435.2 | F57: 6316869.6 | G57: 1725651 | H57: 3895638.6 | I57: 550434.46 | J57: 895926.96 | K57: 1641762.5 | L57: 6665457.3 | M57: 44257128 | N57: 0 | O57: 9791175.9 | P57: 7252095.6 | Q57: 96382523 | R57: 50.3607 | S57: 313116.58 | T57: 1264.3429 | U57: 1074640.4 | V57: 10959772 | W57: 10180969 | X57: 23211309 | Y57: 1870932.4 | Z57: 68812.683 | AA57: 454726.91 | AB57: 7008.3792 | AC57: 419825.03 | AD57: 130983.68 | AE57: 252407.93 | AF57: 5115921.6 | AG57: 50163.623 | AH57: 357390.14 | AI57: 54734640 | AJ57: 2930004.1 | AK57: 29965714 | AL57: 1805420.9 | AM57: 4690563.5 | AN57: 801544.93 | AO57: 569719.77 | AP57: 4548711.2 | AQ57: 784188.43 | AR57: 787474.67 | AS57: 14813130 | AT57: 8764045.5 | AU57: 984488.01 | AV57: 1145602.2 | AW57: 577473.25 | AX57: 3859.5358 | AY57: 3691875.5 | AZ57: 361822.06 | BA57: 7687398 | BB57: 4399730.1 | BC57: 3155962.8 | BD57: 1760285.7 | BE57: 0 | BF57: 3.9132828e+08 | BG57: 2.6396169e+08 | BH57: 38864456 | BI57: 1.7024103e+08 | BJ57: -2235762.8 | BK57: 2.6602336e+08 | BL57: 7.3685477e+08 | BM57: 1.1281831e+09 | BN57: 0 | BO57: 0 | BP57: 1.1281831e+09 | BQ57: 1.1281831e+09
A58: 200 | B58: Input Antara Impor | C58: 791206.13 | D58: 375015.64 | E58: 10486.257 | F58: 1047653.9 | G58: 30889.601 | H58: 1247792.6 | I58: 81133.536 | J58: 244472.75 | K58: 482112.46 | L58: 4388044.3 | M58: 16249141 | N58: 0 | O58: 3856568.4 | P58: 4506950.6 | Q58: 20140362 | R58: 628.9601 | S58: 240573.43 | T58: 591.9933 | U58: 481090.11 | V58: 4100412.2 | W58: 4865736.2 | X58: 7485108.9 | Y58: 242106.94 | Z58: 95536.518 | AA58: 619960.15 | AB58: 25619.018 | AC58: 685557.65 | AD58: 108923.47 | AE58: 230582.68 | AF58: 223639.74 | AG58: 2175.882 | AH58: 85678.691 | AI58: 47641645 | AJ58: 1776608.5 | AK58: 11740012 | AL58: 284577.11 | AM58: 1473237.1 | AN58: 209371.52 | AO58: 191470.61 | AP58: 1844824.4 | AQ58: 290366.84 | AR58: 185816.52 | AS58: 3101724.1 | AT58: 4194487.9 | AU58: 676431.5 | AV58: 508728.46 | AW58: 284257.83 | AX58: 2042.9631 | AY58: 850142.64 | AZ58: 198642.53 | BA58: 2651406.5 | BB58: 1903499.1 | BC58: 867220.87 | BD58: 621315.39 | BE58: 0 | BF58: 1.5444358e+08 | BG58: 1.2965198e+08 | BH58: 1431388.6 | BI58: 21622265 | BJ58: 0 | BK58: 0 | BL58: 1.5270563e+08 | BM58: 3.0714921e+08 | BN58: 3.0714921e+08 | BO58: 0 | BP58: 0 | BQ58: 3.0714921e+08 | BU58: MEDIAN | BV58: =MEDIAN(BV2:BV56) -> 0.57658079
A59: 201 | B59: Kompensasi Tenaga Kerja | C59: 5832812.2 | D59: 1851198.6 | E59: 3860684.2 | F59: 6957374.1 | G59: 1323432.8 | H59: 4019857.3 | I59: 729301.56 | J59: 3272004.5 | K59: 6038698.3 | L59: 5889766.4 | M59: 8563767.6 | N59: 0 | O59: 11920661 | P59: 3237441.4 | Q59: 16172781 | R59: 127.6953 | S59: 87834.296 | T59: 759.4107 | U59: 401808.37 | V59: 3723700.8 | W59: 1935170.2 | X59: 3850793.7 | Y59: 771312.5 | Z59: 13273.166 | AA59: 271293.01 | AB59: 7056.9827 | AC59: 45080.606 | AD59: 80306.659 | AE59: 139591.25 | AF59: 333821.81 | AG59: 18359.857 | AH59: 176337.22 | AI59: 29817694 | AJ59: 4895800.6 | AK59: 35240856 | AL59: 1517369.4 | AM59: 1480223.6 | AN59: 120405.68 | AO59: 212984.25 | AP59: 1550942.4 | AQ59: 545820.53 | AR59: 497994.94 | AS59: 5956839.8 | AT59: 5876975.7 | AU59: 3874819.1 | AV59: 1349774.3 | AW59: 799985.19 | AX59: 4062.7106 | AY59: 1604043.2 | AZ59: 351607.95 | BA59: 11241529 | BB59: 9986107.5 | BC59: 2123614.1 | BD59: 2206519.1 | BE59: 0 | BF59: 2.1278238e+08 | BG59: 0 | BH59: 0 | BI59: 0 | BJ59: 0 | BK59: 0 | BL59: 0 | BM59: 0 | BN59: 0 | BO59: 0 | BP59: 0 | BQ59: 0 | BU59: Min | BV59: =MIN(BV2:BV56) -> 0
A60: 202 | B60: Surplus Usaha (termasuk pendapatan campuran) Bruto | C60: 8301724.9 | D60: 3417178 | E60: 4430146.8 | F60: 8639149.2 | G60: 1747335.6 | H60: 3939592.9 | I60: 711635.02 | J60: 5009982.1 | K60: 9651785.6 | L60: 24288684 | M60: 37866401 | N60: 0 | O60: 17589721 | P60: 17052949 | Q60: 38725196 | R60: 346.8566 | S60: 92742.361 | T60: 374.9103 | U60: 577686.99 | V60: 3739406.3 | W60: 5599336.4 | X60: 7163823.7 | Y60: 753166.35 | Z60: 33451.696 | AA60: 263247.8 | AB60: 7349.3408 | AC60: 40161.505 | AD60: 77779.569 | AE60: 133284.67 | AF60: 1135677.9 | AG60: 105185.31 | AH60: 407606.64 | AI60: 33304679 | AJ60: 5590404.9 | AK60: 45486996 | AL60: 494158.3 | AM60: 4685255.1 | AN60: 312533.01 | AO60: 357200.86 | AP60: 2174799.4 | AQ60: 908284.61 | AR60: 951701.15 | AS60: 5436133 | AT60: 14522960 | AU60: 4362542.7 | AV60: 1999175.6 | AW60: 775295.46 | AX60: 5629.8589 | AY60: 17983268 | AZ60: 365503.24 | BA60: 5434543.5 | BB60: 3558443.7 | BC60: 1904269.1 | BD60: 2086452.6 | BE60: 0 | BF60: 3.5420234e+08 | BG60: 0 | BH60: 0 | BI60: 0 | BJ60: 0 | BK60: 0 | BL60: 0 | BM60: 0 | BN60: 0 | BO60: 0 | BP60: 0 | BQ60: 0 | BU60: Q1 | BV60: =_xlfn.QUARTILE.INC(BV2:BV56,1) -> 0.3824168
A61: 203 | B61: Pajak Atas Produksi Lainnya | C61: 287184.91 | D61: 49973.142 | E61: 131454.42 | F61: 710029.09 | G61: 21141.433 | H61: 36137.845 | I61: 8472.7813 | J61: 70381.682 | K61: 79836.204 | L61: 246984.56 | M61: 482279.76 | N61: 0 | O61: 560630.61 | P61: -295803.02 | Q61: 3729208.8 | R61: 669.6909 | S61: 19649.662 | T61: 109.5067 | U61: 25374.595 | V61: 607497.68 | W61: 438577.73 | X61: 1273793.7 | Y61: 64363.323 | Z61: 7901.5949 | AA61: 104114.11 | AB61: 5078.9987 | AC61: 12457.124 | AD61: 19384.312 | AE61: 32607.685 | AF61: -713391.1 | AG61: 264.9102 | AH61: 21769.143 | AI61: 4085600.4 | AJ61: 166336.03 | AK61: 426445.12 | AL61: -512190.24 | AM61: 74359.511 | AN61: -14735.86 | AO61: 8585.6602 | AP61: 149766.51 | AQ61: 9144.3348 | AR61: 114274.24 | AS61: 1011776.5 | AT61: 631322.27 | AU61: 20323.173 | AV61: 10824.496 | AW61: 8876.7999 | AX61: 51.8209 | AY61: 992818.37 | AZ61: 9668.9809 | BA61: 0 | BB61: 23542.654 | BC61: 37622.525 | BD61: 133924.06 | BE61: 0 | BF61: 15426472 | BG61: 0 | BH61: 0 | BI61: 0 | BJ61: 0 | BK61: 0 | BL61: 0 | BM61: 0 | BN61: 0 | BO61: 0 | BP61: 0 | BQ61: 0 | BU61: Q2 | BV61: =_xlfn.QUARTILE.INC(BV2:BV56,2) -> 0.57658079
A62: 204 | B62: Subsidi Atas Produksi Lainnya (-) | C62: 0 | D62: 0 | E62: 0 | F62: 0 | G62: 0 | H62: 0 | I62: 0 | J62: 0 | K62: 0 | L62: 0 | M62: 0 | N62: 0 | O62: 0 | P62: 0 | Q62: 0 | R62: 0 | S62: 0 | T62: 0 | U62: 0 | V62: 0 | W62: 0 | X62: 0 | Y62: 0 | Z62: 0 | AA62: 0 | AB62: 0 | AC62: 0 | AD62: 0 | AE62: 0 | AF62: 0 | AG62: 0 | AH62: 0 | AI62: 0 | AJ62: 0 | AK62: 0 | AL62: 0 | AM62: 0 | AN62: 0 | AO62: 0 | AP62: 0 | AQ62: 0 | AR62: 0 | AS62: 0 | AT62: 0 | AU62: 0 | AV62: 0 | AW62: 0 | AX62: 0 | AY62: 0 | AZ62: 0 | BA62: 0 | BB62: 0 | BC62: 0 | BD62: 0 | BE62: 0 | BF62: 0 | BG62: 0 | BH62: 0 | BI62: 0 | BJ62: 0 | BK62: 0 | BL62: 0 | BM62: 0 | BN62: 0 | BO62: 0 | BP62: 0 | BQ62: 0 | BU62: Q3 | BV62: =_xlfn.QUARTILE.INC(BV2:BV56,3) -> 0.67643116
A63: 209 | B63: Nilai Tambah Bruto | C63: 14421722 | D63: 5318349.7 | E63: 8422285.4 | F63: 16306552 | G63: 3091909.9 | H63: 7995588.1 | I63: 1449409.4 | J63: 8352368.3 | K63: 15770320 | L63: 30425435 | M63: 46912449 | N63: 0 | O63: 30071012 | P63: 19994588 | Q63: 58627186 | R63: 1144.2429 | S63: 200226.32 | T63: 1243.8277 | U63: 1004870 | V63: 8070604.8 | W63: 7973084.3 | X63: 12288411 | Y63: 1588842.2 | Z63: 54626.457 | AA63: 638654.93 | AB63: 19485.322 | AC63: 97699.234 | AD63: 177470.54 | AE63: 305483.61 | AF63: 756108.59 | AG63: 123810.07 | AH63: 605713 | AI63: 67207973 | AJ63: 10652542 | AK63: 81154297 | AL63: 1499337.4 | AM63: 6239838.2 | AN63: 418202.82 | AO63: 578770.77 | AP63: 3875508.4 | AQ63: 1463249.5 | AR63: 1563970.3 | AS63: 12404749 | AT63: 21031258 | AU63: 8257685 | AV63: 3359774.4 | AW63: 1584157.4 | AX63: 9744.3905 | AY63: 20580130 | AZ63: 726780.17 | BA63: 16676073 | BB63: 13568094 | BC63: 4065505.7 | BD63: 4426895.7 | BE63: 0 | BF63: 5.8241119e+08 | BG63: 0 | BH63: 0 | BI63: 0 | BJ63: 0 | BK63: 0 | BL63: 0 | BM63: 0 | BN63: 0 | BO63: 0 | BP63: 0 | BQ63: 0 | BU63: Max | BV63: =MAX(BV2:BV56) -> 0.88130927
A64: 210 | B64: Total Input | C64: 18628421 | D64: 6978109.2 | E64: 12253207 | F64: 23671076 | G64: 4848450.5 | H64: 13139019 | I64: 2080977.3 | J64: 9492768 | K64: 17894195 | L64: 41478936 | M64: 1.0741872e+08 | N64: 0 | O64: 43718756 | P64: 31753634 | Q64: 1.7515007e+08 | R64: 1823.5637 | S64: 753916.33 | T64: 3100.1638 | U64: 2560600.4 | V64: 23130789 | W64: 23019790 | X64: 42984829 | Y64: 3701881.5 | Z64: 218975.66 | AA64: 1713342 | AB64: 52112.72 | AC64: 1203081.9 | AD64: 417377.69 | AE64: 788474.21 | AF64: 6095669.9 | AG64: 176149.58 | AH64: 1048781.8 | AI64: 1.6958426e+08 | AJ64: 15359154 | AK64: 1.2286002e+08 | AL64: 3589335.5 | AM64: 12403639 | AN64: 1429119.3 | AO64: 1339961.1 | AP64: 10269044 | AQ64: 2537804.7 | AR64: 2537261.5 | AS64: 30319604 | AT64: 33989791 | AU64: 9918604.5 | AV64: 5014105.1 | AW64: 2445888.5 | AX64: 15646.889 | AY64: 25122148 | AZ64: 1287244.8 | BA64: 27014877 | BB64: 19871323 | BC64: 8088689.4 | BD64: 6808496.8 | BE64: 0 | BF64: 1.1281831e+09

Sheet DeskripsiSektor
A1: KodeSektor | B1: NamaSektor | C1: NamaPendek | D1: NamaSingkat | E1: KSM | F1: Constrained | G1: Unconstrained | H1: RateUnconstrained | I1: TenagaKerja
A2: 1 | B2: Pertanian Tanaman Pangan | C2: TP | D2: Tanaman pangan | E2: Pertanian, Kehutanan, dan Perikanan | F2: 1 | G2: 0 | H2: 0 | I2: 301420
A3: 2 | B3: Pertanian Tanaman Hortikultura Semusim, Hortikultura Tahunan, dan Lainnya | C3: Hort | D3: Hortikultura | E3: Pertanian, Kehutanan, dan Perikanan | F3: 1 | G3: 0 | H3: 0 | I3: 106345
A4: 3 | B4: Karet | C4: Krt | D4: Karet | E4: Pertanian, Kehutanan, dan Perikanan | F4: 1 | G4: 0 | H4: 0 | I4: 208167
A5: 4 | B5: Kelapa Sawit | C5: KS | D5: Kelapa sawit | E5: Pertanian, Kehutanan, dan Perikanan | F5: 1 | G5: 0 | H5: 0 | I5: 375145
A6: 5 | B6: Tanaman Perkebunan lainnya | C6: TPL | D6: Perkebunan lainnya | E6: Pertanian, Kehutanan, dan Perikanan | F6: 1 | G6: 0 | H6: 0 | I6: 71359
A7: 6 | B7: Peternakan | C7: Ptr | D7: Peternakan | E7: Pertanian, Kehutanan, dan Perikanan | F7: 1 | G7: 0 | H7: 0 | I7: 211536
A8: 7 | B8: Jasa Pertanian dan Perburuan | C8: JPP | D8: Jasa pertanian & perburuan | E8: Pertanian, Kehutanan, dan Perikanan | F8: 0 | G8: 1 | H8: 0.0022891363 | I8: 45609
A9: 8 | B9: Kehutanan dan Penebangan Kayu | C9: KPK | D9: Kehutanan & penebangan kayu | E9: Pertanian, Kehutanan, dan Perikanan | F9: 1 | G9: 0 | H9: 0 | I9: 196766
A10: 9 | B10: Perikanan | C10: Pkn | D10: Perikanan | E10: Pertanian, Kehutanan, dan Perikanan | F10: 1 | G10: 0 | H10: 0 | I10: 365350
A11: 10 | B11: Pertambangan Minyak, Gas dan Panas Bumi | C11: PMGP | D11: Pertambangan migas & panas bumi | E11: Pertambangan dan Penggalian | F11: 0 | G11: 1 | H11: -0.0118 | I11: 50788
A12: 11 | B12: Pertambangan Batubara dan Lignit | C12: PBL | D12: Pertambangan batubara | E12: Pertambangan dan Penggalian | F12: 0 | G12: 1 | H12: 0.1359 | I12: 31620
A13: 12 | B13: Pertambangan Bijih Logam | C13: PBjL | D13: Pertambangan bijih logam | E13: Pertambangan dan Penggalian | F13: 0 | G13: 1 | H13: 0 | I13: 0
... A56: 55 | B56: Sektor lain yang tidak jelas batasannya | C56: SLTJ | D56: Sektor lainnya | E56: Jasa Lainnya | F56: 0 | G56: 1 | H56: 0 | I56: 0

Sheet LDC Draft
A1: ID | B1: Land Cover | C1: Tanaman Pangan | D1: Tanaman Hortikultura | E1: Karet | F1: Kelapa Sawit | G1: Tanaman Perkebunan lainnya | H1: Peternakan | I1: Kehutanan | J1: Perikanan | K1: Peruntukan Lainnya | L1: SUM
A2: 1 | B2: Hutan lahan kering primer
A3: 2 | B3: Hutan sekunder kerapatan tinggi
A4: 3 | B4: Hutan sekunder kerapatan rendah
A5: 4 | B5: Hutan rawa primer
A6: 5 | B6: Hutan rawa sekunder
A7: 6 | B7: Hutan mangrove primer
A8: 7 | B8: Hutan mangrove sekunder
A9: 8 | B9: Tanaman kayu industri
A10: 9 | B10: Kebun campuran
A11: 10 | B11: Agroforestri kopi
A12: 11 | B12: Karet agroforestri | C12: 0.05 | E12: 0.5 | G12: 0.1 | K12: 0.35 | L12: =SUM(C12:K12) -> 1
A13: 12 | B13: Karet monokultur
A14: 13 | B14: Kelapa sawit skala besar
A15: 14 | B15: Kelapa sawit skala kecil
A16: 15 | B16: Kelapa
A17: 16 | B17: Teh
A18: 17 | B18: Sawah irigasi
A19: 18 | B19: Sawah tadah hujan
A20: 19 | B20: Tebu
A21: 20 | B21: Tanaman semusim lain
A22: 21 | B22: Semak belukar
A23: 22 | B23: Rerumputan
A24: 23 | B24: Tambang
... A28: 27 | B28: Tubuh air
A30: PENJELASAN
A31: Petunjuk Pengisian 1. Baris menunjukkan jenis tutupan lahan, sedangkan kolom menunjukkan jenis komoditas. 2. Pilih satu baris tutupan lahan, misalnya karet agroforestri. 3. Periksa setiap kolom untuk menentukan komoditas apa saja yang terdapat pada tutupan lahan tersebut dan perkirakan persentase luasnya. 4. Ulangi langkah yang sama untuk seluruh jenis tutupan lahan. 5. Periksa kolom SUM. Total persentase pada setiap baris harus 100% (atau 1 dalam format desimal). Contoh Pengisian Pada tutupan lahan karet agroforestri: - Karet: 50% - Tanaman pangan (misalnya jagung): 5% - Tanaman perkebunan lainnya: 10% - Peruntukan lainnya: 35% Interpretasi: Tutupan lahan karet agroforestri terdiri atas 50% karet, 5% tanaman pangan, 10% tanaman perkebunan lainnya, dan 35% sisanya adalah peruntukan lainnya.

Sheet BAU_Lahan
A1: ID | B1: Land Cover | C1: 2025 | D1: 2030 | E1: 2035 | F1: 2040 | G1: 2045 | H1: CAGR 1 | I1: CAGR 2 | J1: CAGR 3 | K1: CAGR 4 | L1: 2025 | M1: 2026 | N1: 2027 | O1: 2028 | P1: 2029 | Q1: 2030 | R1: 2031 | S1: 2032 | T1: 2033 | U1: 2034 | V1: 2035 | W1: 2036 | X1: 2037 | Y1: 2038 | Z1: 2039 | AA1: 2040 | AB1: 2041 | AC1: 2042 | AD1: 2043 | AE1: 2044 | AF1: 2045
A2: 1 | B2: Hutan lahan kering primer | C2: 281147 | D2: 248530 | E2: 234183 | F2: 226435 | G2: 221810 | H2: =((D2/C2)^(1/5))-1 -> -0.024361178 | I2: =((E2/D2)^(1/5))-1 -> -0.011821708 | J2: =((F2/E2)^(1/5))-1 -> -0.0067063977 | K2: =((G2/F2)^(1/5))-1 -> -0.0041188479 | L2: =C2 -> 281147 | M2: =C2*(1+H2) -> 274297.93 | N2: =M2*(1+$H2) -> 267615.71 | O2: =N2*(1+$H2) -> 261096.27 | P2: =O2*(1+$H2) -> 254735.66 | Q2: =P2*(1+$H2) -> 248530 | R2: =D2*(1+I2) -> 245591.95 | S2: =R2*(1+$I2) -> 242688.63 | T2: =S2*(1+$I2) -> 239819.64 | U2: =T2*(1+$I2) -> 236984.56 | V2: =U2*(1+$I2) -> 234183 | W2: =E2*(1+J2) -> 232612.48 | X2: =W2*(1+$J2) -> 231052.48 | Y2: =X2*(1+$J2) -> 229502.95 | Z2: =Y2*(1+$J2) -> 227963.82 | AA2: =Z2*(1+$J2) -> 226435 | AB2: =F2*(1+K2) -> 225502.35 | AC2: =AB2*(1+$K2) -> 224573.54 | AD2: =AC2*(1+$K2) -> 223648.55 | AE2: =AD2*(1+$K2) -> 222727.38 | AF2: =AE2*(1+$K2) -> 221810
A3: 2 | B3: Hutan sekunder kerapatan tinggi | C3: 268650 | D3: 262724 | E3: 254254 | F3: 243165 | G3: 231391 | H3: =((D3/C3)^(1/5))-1 -> -0.0044511373 | I3: =((E3/D3)^(1/5))-1 -> -0.0065326258 | J3: =((F3/E3)^(1/5))-1 -> -0.0088790547 | K3: =((G3/F3)^(1/5))-1 -> -0.0098771583 | L3: =C3 -> 268650 | M3: =C3*(1+H3) -> 267454.2 | N3: =M3*(1+$H3) -> 266263.73 | O3: =N3*(1+$H3) -> 265078.55 | P3: =O3*(1+$H3) -> 263898.65 | Q3: =P3*(1+$H3) -> 262724 | R3: =D3*(1+I3) -> 261007.72 | S3: =R3*(1+$I3) -> 259302.66 | T3: =S3*(1+$I3) -> 257608.73 | U3: =T3*(1+$I3) -> 255925.87 | V3: =U3*(1+$I3) -> 254254 | W3: =E3*(1+J3) -> 251996.46 | X3: =W3*(1+$J3) -> 249758.97 | Y3: =X3*(1+$J3) -> 247541.35 | Z3: =Y3*(1+$J3) -> 245343.42 | AA3: =Z3*(1+$J3) -> 243165 | AB3: =F3*(1+K3) -> 240763.22 | AC3: =AB3*(1+$K3) -> 238385.16 | AD3: =AC3*(1+$K3) -> 236030.6 | AE3: =AD3*(1+$K3) -> 233699.28 | AF3: =AE3*(1+$K3) -> 231391
A4: 3 | B4: Hutan sekunder kerapatan rendah | C4: 182483 | D4: 203346 | E4: 221991 | F4: 234159 | G4: 244359 | H4: =((D4/C4)^(1/5))-1 -> 0.021886459 | I4: =((E4/D4)^(1/5))-1 -> 0.017700404 | J4: =((F4/E4)^(1/5))-1 -> 0.010729863 | K4: =((G4/F4)^(1/5))-1 -> 0.0085640804 | L4: =C4 -> 182483 | M4: =C4*(1+H4) -> 186476.91 | N4: =M4*(1+$H4) -> 190558.23 | O4: =N4*(1+$H4) -> 194728.87 | P4: =O4*(1+$H4) -> 198990.8 | Q4: =P4*(1+$H4) -> 203346 | R4: =D4*(1+I4) -> 206945.31 | S4: =R4*(1+$I4) -> 210608.32 | T4: =S4*(1+$I4) -> 214336.17 | U4: =T4*(1+$I4) -> 218130.01 | V4: =U4*(1+$I4) -> 221991 | W4: =E4*(1+J4) -> 224372.93 | X4: =W4*(1+$J4) -> 226780.42 | Y4: =X4*(1+$J4) -> 229213.75 | Z4: =Y4*(1+$J4) -> 231673.18 | AA4: =Z4*(1+$J4) -> 234159 | AB4: =F4*(1+K4) -> 236164.36 | AC4: =AB4*(1+$K4) -> 238186.89 | AD4: =AC4*(1+$K4) -> 240226.74 | AE4: =AD4*(1+$K4) -> 242284.06 | AF4: =AE4*(1+$K4) -> 244359
A5: 4 | B5: Hutan rawa primer | C5: 34376 | D5: 32885 | E5: 31890 | F5: 31143 | G5: 30486 | H5: =((D5/C5)^(1/5))-1 -> -0.0088291956 | I5: =((E5/D5)^(1/5))-1 -> -0.0061259883 | J5: =((F5/E5)^(1/5))-1 -> -0.0047293771 | K5: =((G5/F5)^(1/5))-1 -> -0.0042553082 | L5: =C5 -> 34376 | M5: =C5*(1+H5) -> 34072.488 | N5: =M5*(1+$H5) -> 33771.655 | O5: =N5*(1+$H5) -> 33473.478 | P5: =O5*(1+$H5) -> 33177.934 | Q5: =P5*(1+$H5) -> 32885 | R5: =D5*(1+I5) -> 32683.547 | S5: =R5*(1+$I5) -> 32483.328 | T5: =S5*(1+$I5) -> 32284.335 | U5: =T5*(1+$I5) -> 32086.562 | V5: =U5*(1+$I5) -> 31890 | W5: =E5*(1+J5) -> 31739.18 | X5: =W5*(1+$J5) -> 31589.074 | Y5: =X5*(1+$J5) -> 31439.677 | Z5: =Y5*(1+$J5) -> 31290.987 | AA5: =Z5*(1+$J5) -> 31143 | AB5: =F5*(1+K5) -> 31010.477 | AC5: =AB5*(1+$K5) -> 30878.518 | AD5: =AC5*(1+$K5) -> 30747.12 | AE5: =AD5*(1+$K5) -> 30616.282 | AF5: =AE5*(1+$K5) -> 30486
A6: 5 | B6: Hutan rawa sekunder | C6: 436939 | D6: 434757 | E6: 432589 | F6: 430441 | G6: 428303 | H6: =((D6/C6)^(1/5))-1 -> -0.0010007675 | I6: =((E6/D6)^(1/5))-1 -> -0.00099933409 | J6: =((F6/E6)^(1/5))-1 -> -0.00099506879 | K6: =((G6/F6)^(1/5))-1 -> -0.00099537938 | L6: =C6 -> 436939 | M6: =C6*(1+H6) -> 436501.73 | N6: =M6*(1+$H6) -> 436064.89 | O6: =N6*(1+$H6) -> 435628.49 | P6: =O6*(1+$H6) -> 435192.53 | Q6: =P6*(1+$H6) -> 434757 | R6: =D6*(1+I6) -> 434322.53 | S6: =R6*(1+$I6) -> 433888.5 | T6: =S6*(1+$I6) -> 433454.9 | U6: =T6*(1+$I6) -> 433021.73 | V6: =U6*(1+$I6) -> 432589 | W6: =E6*(1+J6) -> 432158.54 | X6: =W6*(1+$J6) -> 431728.52 | Y6: =X6*(1+$J6) -> 431298.92 | Z6: =Y6*(1+$J6) -> 430869.75 | AA6: =Z6*(1+$J6) -> 430441 | AB6: =F6*(1+K6) -> 430012.55 | AC6: =AB6*(1+$K6) -> 429584.52 | AD6: =AC6*(1+$K6) -> 429156.92 | AE6: =AD6*(1+$K6) -> 428729.75 | AF6: =AE6*(1+$K6) -> 428303
A7: 6 | B7: Hutan mangrove primer | C7: 99848 | D7: 100046 | E7: 98372 | F7: 96947 | G7: 95654 | H7: =((D7/C7)^(1/5))-1 -> 0.00039628862 | I7: =((E7/D7)^(1/5))-1 -> -0.0033690858 | J7: =((F7/E7)^(1/5))-1 -> -0.0029141004 | K7: =((G7/F7)^(1/5))-1 -> -0.0026817822 | L7: =C7 -> 99848 | M7: =C7*(1+H7) -> 99887.569 | N7: =M7*(1+$H7) -> 99927.153 | O7: =N7*(1+$H7) -> 99966.753 | P7: =O7*(1+$H7) -> 100006.37 | Q7: =P7*(1+$H7) -> 100046 | R7: =D7*(1+I7) -> 99708.936 | S7: =R7*(1+$I7) -> 99373.008 | T7: =S7*(1+$I7) -> 99038.212 | U7: =T7*(1+$I7) -> 98704.544 | V7: =U7*(1+$I7) -> 98372 | W7: =E7*(1+J7) -> 98085.334 | X7: =W7*(1+$J7) -> 97799.504 | Y7: =X7*(1+$J7) -> 97514.506 | Z7: =Y7*(1+$J7) -> 97230.339 | AA7: =Z7*(1+$J7) -> 96947 | AB7: =F7*(1+K7) -> 96687.009 | AC7: =AB7*(1+$K7) -> 96427.716 | AD7: =AC7*(1+$K7) -> 96169.118 | AE7: =AD7*(1+$K7) -> 95911.213 | AF7: =AE7*(1+$K7) -> 95654
